<?xml version="1.0" encoding="utf-8"?>
<!-- This URDF was automatically created by SolidWorks to URDF Exporter! Originally created by Stephen Brawner (brawner@gmail.com) 
     Commit Version: 1.6.0-4-g7f85cfe  Build Version: 1.6.7995.38578
     For more information, please see http://wiki.ros.org/sw_urdf_exporter -->
<robot
  name="PAI-urdf">

  <!-- <xacro:include filename="$(find pai_description)/xacro/gazebo.xacro"/> -->
  <gazebo>
        <plugin name="gazebo_ros_control" filename="libgazebo_ros_control.so">
            <robotNamespace>/pai_gazebo</robotNamespace>
            <robotSimType>gazebo_ros_control/DefaultRobotHWSim</robotSimType>
        </plugin>
    </gazebo>

    <!-- Show the trajectory of trunk center. -->
    <gazebo>
        <plugin name="3dplot" filename="libLinkPlot3DPlugin.so">
            <frequency>10</frequency>
            <plot>
                <link>base_link</link>
                <pose>0 0 0 0 0 0</pose>
                <material>Gazebo/Yellow</material>
            </plot>
        </plugin>
    </gazebo>

    <gazebo>
        <plugin filename="libgazebo_ros_force.so" name="gazebo_ros_force">
            <bodyName>base_link</bodyName>
            <topicName>/apply_force/trunk</topicName>
        </plugin>
    </gazebo>

    <gazebo reference="base_link">
        <gravity>true</gravity>
        <sensor name="imu_sensor" type="imu">
            <always_on>true</always_on>
            <update_rate>1000</update_rate>
            <visualize>true</visualize>
            <topic>__default_topic__</topic>
            <plugin filename="libgazebo_ros_imu_sensor.so" name="imu_plugin">
                <topicName>trunk_imu</topicName>
                <bodyName>imu_link</bodyName>
                <updateRateHZ>1000.0</updateRateHZ>
                <gaussianNoise>0.00</gaussianNoise>
                <xyzOffset>0 0 0</xyzOffset>
                <rpyOffset>0 0 0</rpyOffset>
                <frameName>imu_link</frameName>
            </plugin>
            <pose>0 0 0 0 0 0</pose>
        </sensor>
    </gazebo>


    <gazebo reference="base_link">
        <mu1>0.2</mu1>
        <mu2>0.2</mu2>
        <material>Gazebo/DarkGrey</material>
    </gazebo>

     <gazebo reference="trunkcol">
        <mu1>0.2</mu1>
        <mu2>0.2</mu2>
       
    </gazebo>



    <!-- L leg -->
    <gazebo reference="L_hip">
        <mu1>1</mu1>
        <mu2>1</mu2>
        <kp  value="100000.0"/>
        <kd  value="1000.0"/>
        <material>Gazebo/Grey</material>
    </gazebo>
    <gazebo reference="L_hip2">
        <mu1>1</mu1>
        <mu2>1</mu2>
        <kp  value="100000.0"/>
        <kd  value="1000.0"/>
        <material>Gazebo/Grey</material>
    </gazebo>
    <gazebo reference="L_thigh">
        <mu1>1</mu1>
        <mu2>1</mu2>
        <kp  value="100000.0"/>
        <kd  value="1000.0"/>
        <self_collide>0</self_collide>
        <material>Gazebo/Grey</material>
        
    </gazebo>
    <gazebo reference="L_calf">
        <mu1>1</mu1>
        <mu2>1</mu2>
        <kp  value="100000.0"/>
        <kd  value="1000.0"/>
        <self_collide>0</self_collide>
        <material>Gazebo/Grey</material>
    </gazebo>
    <gazebo reference="L_toe">
        <mu1>3</mu1>
        <mu2>3</mu2>
        <kp  value="1000000.0"/>
        <kd  value="1000.0"/>
        <self_collide>0</self_collide>
        <material>Gazebo/Grey</material>
        
    </gazebo>

    <!--R leg -->
    <gazebo reference="R_hip">
        <mu1>1</mu1>
        <mu2>1</mu2>
        <kp  value="100000.0"/>
        <kd  value="1000.0"/>
        <material>Gazebo/Grey</material>
    </gazebo>
    <gazebo reference="R_hip2">
        <mu1>1</mu1>
        <mu2>1</mu2>
        <kp  value="100000.0"/>
        <kd  value="1000.0"/>
        <material>Gazebo/Grey</material>
    </gazebo>
    <gazebo reference="R_thigh">
        <mu1>1</mu1>
        <mu2>1</mu2>
        <kp  value="100000.0"/>
        <kd  value="1000.0"/>
        <self_collide>0</self_collide>
        <material>Gazebo/Grey</material>
    </gazebo>
    <gazebo reference="R_calf">
        <mu1>1</mu1>
        <mu2>1</mu2>
        <kp  value="100000.0"/>
        <kd  value="1000.0"/>
        <self_collide>0</self_collide>
        <material>Gazebo/Grey</material>
    </gazebo>
    <gazebo reference="R_toe">
        <mu1>3</mu1>
        <mu2>3</mu2>
        <kp  value="1000000.0"/>
        <kd  value="1000.0"/>
        <self_collide>0</self_collide>
        <material>Gazebo/Grey</material>
        
    </gazebo>

  <link
    name="base_link">
    <inertial>
      <origin
        xyz="0.069429 6.1599E-18 0.093307"
        rpy="0 0 0" />
      <mass
        value="1.5" />
      <inertia
        ixx="0.0028787"
        ixy="-6.2028E-19"
        ixz="0.0011496"
        iyy="0.0047606"
        iyz="5.6278E-19"
        izz="0.0043029" />
    </inertial>
    <visual>
      <origin
        xyz="0 0 0"
        rpy="0 0 0" />
      <geometry>
        <mesh
          filename="package://pai_description/meshes/base_link.STL" />
      </geometry>
      <material
        name="">
        <color
          rgba="1 1 1 1" />
      </material>
    </visual>
    <collision>
      <origin
        xyz="0 0 0"
        rpy="0 0 0" />
      <geometry>
        <mesh
          filename="package://pai_description/meshes/base_link.STL" />
      </geometry>
    </collision>
  </link>
  <link
    name="L_hip">
    <inertial>
      <origin
        xyz="0.041409 0 0.055119"
        rpy="0 0 0" />
      <mass
        value="0.35" />
      <inertia
        ixx="3.6841E-05"
        ixy="-2.584E-22"
        ixz="-6.2162E-07"
        iyy="3.8839E-05"
        iyz="-1.9482E-21"
        izz="3.6277E-05" />
    </inertial>
    <visual>
      <origin
        xyz="0 0 0"
        rpy="0 0 0" />
      <geometry>
        <mesh
          filename="package://pai_description/meshes/L_hip.STL" />
      </geometry>
      <material
        name="">
        <color
          rgba="1 1 1 1" />
      </material>
    </visual>
    <collision>
      <origin
        xyz="0 0 0"
        rpy="0 0 0" />
      <geometry>
        <mesh
          filename="package://pai_description/meshes/L_hip.STL" />
      </geometry>
    </collision>
  </link>
  <joint
    name="L_hip_joint"
    type="continuous">
    <origin
      xyz="0 0.075 0"
      rpy="0 0 0" />
    <parent
      link="base_link" />
    <child
      link="L_hip" />
    <axis
      xyz="-1 0 0" />
  </joint>
  <link
    name="L_hip2">
    <inertial>
      <origin
        xyz="-0.00049584 2.8866E-15 0.0032955"
        rpy="0 0 0" />
      <mass
        value="0.65" />
      <inertia
        ixx="6.7757E-05"
        ixy="7.9552E-21"
        ixz="-6.395E-07"
        iyy="6.8581E-05"
        iyz="9.1346E-21"
        izz="6.7914E-05" />
    </inertial>
    <visual>
      <origin
        xyz="0 0 0"
        rpy="0 0 0" />
      <geometry>
        <mesh
          filename="package://pai_description/meshes/L_hip2.STL" />
      </geometry>
      <material
        name="">
        <color
          rgba="1 1 1 1" />
      </material>
    </visual>
    <collision>
      <origin
        xyz="0 0 0"
        rpy="0 0 0" />
      <geometry>
        <mesh
          filename="package://pai_description/meshes/L_hip2.STL" />
      </geometry>
    </collision>
  </link>
  <joint
    name="L_hip2_joint"
    type="continuous">
    <origin
      xyz="0.049 0 -0.0005"
      rpy="0 0 0" />
    <parent
      link="L_hip" />
    <child
      link="L_hip2" />
    <axis
      xyz="0 0 1" />
  </joint>
  <link
    name="L_thigh">
    <inertial>
      <origin
        xyz="6.5226E-16 2.3315E-15 -0.05727"
        rpy="0 0 0" />
      <mass
        value="0.2" />
      <inertia
        ixx="0.00012318"
        ixy="3.9623E-20"
        ixz="-2.6324E-20"
        iyy="0.00012926"
        iyz="7.2271E-23"
        izz="6.3186E-06" />
    </inertial>
    <visual>
      <origin
        xyz="0 0 0"
        rpy="0 0 0" />
      <geometry>
        <mesh
          filename="package://pai_description/meshes/L_thigh.STL" />
      </geometry>
      <material
        name="">
        <color
          rgba="1 1 1 1" />
      </material>
    </visual>
    <collision>
      <origin
        xyz="0 0 0"
        rpy="0 0 0" />
      <geometry>
        <mesh
          filename="package://pai_description/meshes/L_thigh.STL" />
      </geometry>
    </collision>
  </link>
  <joint
    name="L_thigh_joint"
    type="continuous">
    <origin
      xyz="0 0 0"
      rpy="0 0 0" />
    <parent
      link="L_hip2" />
    <child
      link="L_thigh" />
    <axis
      xyz="0 1 0" />
  </joint>
  <link
    name="L_calf">
    <inertial>
      <origin
        xyz="-0.0045962 0.012568 -0.063722"
        rpy="0 0 0" />
      <mass
        value="0.36" />
      <inertia
        ixx="0.00011945"
        ixy="6.4077E-08"
        ixz="3.3225E-07"
        iyy="0.00012253"
        iyz="1.2844E-07"
        izz="2.0036E-05" />
    </inertial>
    <visual>
      <origin
        xyz="0 0 0"
        rpy="0 0 0" />
      <geometry>
        <mesh
          filename="package://pai_description/meshes/L_calf.STL" />
      </geometry>
      <material
        name="">
        <color
          rgba="1 1 1 1" />
      </material>
    </visual>
    <collision>
      <origin
        xyz="0 0 0"
        rpy="0 0 0" />
      <geometry>
        <mesh
          filename="package://pai_description/meshes/L_calf.STL" />
      </geometry>
    </collision>
  </link>
  <joint
    name="L_calf_joint"
    type="continuous">
    <origin
      xyz="0 0 -0.15"
      rpy="0 0 0" />
    <parent
      link="L_thigh" />
    <child
      link="L_calf" />
    <axis
      xyz="0 1 0" />
  </joint>
  <link
    name="L_toe">
    <inertial>
      <origin
        xyz="0.010818 -1.9984E-08 -0.014672"
        rpy="0 0 0" />
      <mass
        value="0.09" />
      <inertia
        ixx="2.76E-06"
        ixy="3.1498E-11"
        ixz="1.0465E-06"
        iyy="2.7107E-05"
        iyz="3.7297E-13"
        izz="2.6942E-05" />
    </inertial>
    <visual>
      <origin
        xyz="0 0 0"
        rpy="0 0 0" />
      <geometry>
        <mesh
          filename="package://pai_description/meshes/L_toe.STL" />
      </geometry>
      <material
        name="">
        <color
          rgba="1 1 1 1" />
      </material>
    </visual>
    <collision>
      <origin
        xyz="0 0 0"
        rpy="0 0 0" />
      <geometry>
        <mesh
          filename="package://pai_description/meshes/L_toe.STL" />
      </geometry>
    </collision>
  </link>
  <joint
    name="L_toe_joint"
    type="continuous">
    <origin
      xyz="0 0 -0.16"
      rpy="0 0 0" />
    <parent
      link="L_calf" />
    <child
      link="L_toe" />
    <axis
      xyz="0 1 0" />
  </joint>
  <link
    name="R_hip">
    <inertial>
      <origin
        xyz="0.041409 -2.7756E-17 0.055119"
        rpy="0 0 0" />
      <mass
        value="0.35" />
      <inertia
        ixx="3.6841E-05"
        ixy="2.4386E-22"
        ixz="-6.2162E-07"
        iyy="3.8839E-05"
        iyz="-2.348E-21"
        izz="3.6277E-05" />
    </inertial>
    <visual>
      <origin
        xyz="0 0 0"
        rpy="0 0 0" />
      <geometry>
        <mesh
          filename="package://pai_description/meshes/R_hip.STL" />
      </geometry>
      <material
        name="">
        <color
          rgba="1 1 1 1" />
      </material>
    </visual>
    <collision>
      <origin
        xyz="0 0 0"
        rpy="0 0 0" />
      <geometry>
        <mesh
          filename="package://pai_description/meshes/R_hip.STL" />
      </geometry>
    </collision>
  </link>
  <joint
    name="R_hip_joint"
    type="continuous">
    <origin
      xyz="0 -0.075 0"
      rpy="0 0 0" />
    <parent
      link="base_link" />
    <child
      link="R_hip" />
    <axis
      xyz="-1 0 0" />
  </joint>
  <link
    name="R_hip2">
    <inertial>
      <origin
        xyz="-0.00049584 4.3021E-16 0.0032955"
        rpy="0 0 0" />
      <mass
        value="0.65" />
      <inertia
        ixx="6.7757E-05"
        ixy="-1.4631E-21"
        ixz="-6.395E-07"
        iyy="6.8581E-05"
        iyz="1.1283E-20"
        izz="6.7914E-05" />
    </inertial>
    <visual>
      <origin
        xyz="0 0 0"
        rpy="0 0 0" />
      <geometry>
        <mesh
          filename="package://pai_description/meshes/R_hip2.STL" />
      </geometry>
      <material
        name="">
        <color
          rgba="1 1 1 1" />
      </material>
    </visual>
    <collision>
      <origin
        xyz="0 0 0"
        rpy="0 0 0" />
      <geometry>
        <mesh
          filename="package://pai_description/meshes/R_hip2.STL" />
      </geometry>
    </collision>
  </link>
  <joint
    name="R_hip2_joint"
    type="continuous">
    <origin
      xyz="0.049 0 -0.0005"
      rpy="0 0 0" />
    <parent
      link="R_hip" />
    <child
      link="R_hip2" />
    <axis
      xyz="0 0 1" />
  </joint>
  <link
    name="R_thigh">
    <inertial>
      <origin
        xyz="-3.5388E-16 6.5226E-16 -0.05727"
        rpy="0 0 0" />
      <mass
        value="0.2" />
      <inertia
        ixx="0.00012318"
        ixy="3.9681E-20"
        ixz="-3.2905E-21"
        iyy="0.00012926"
        iyz="2.887E-20"
        izz="6.3186E-06" />
    </inertial>
    <visual>
      <origin
        xyz="0 0 0"
        rpy="0 0 0" />
      <geometry>
        <mesh
          filename="package://pai_description/meshes/R_thigh.STL" />
      </geometry>
      <material
        name="">
        <color
          rgba="1 1 1 1" />
      </material>
    </visual>
    <collision>
      <origin
        xyz="0 0 0"
        rpy="0 0 0" />
      <geometry>
        <mesh
          filename="package://pai_description/meshes/R_thigh.STL" />
      </geometry>
    </collision>
  </link>
  <joint
    name="R_thigh_joint"
    type="continuous">
    <origin
      xyz="0 0 0"
      rpy="0 0 0" />
    <parent
      link="R_hip2" />
    <child
      link="R_thigh" />
    <axis
      xyz="0 -1 0" />
  </joint>
  <link
    name="R_calf">
    <inertial>
      <origin
        xyz="-0.0045962 -0.012568 -0.063722"
        rpy="0 0 0" />
      <mass
        value="0.36" />
      <inertia
        ixx="0.00011945"
        ixy="-6.4077E-08"
        ixz="3.3225E-07"
        iyy="0.00012253"
        iyz="-1.2844E-07"
        izz="2.0036E-05" />
    </inertial>
    <visual>
      <origin
        xyz="0 0 0"
        rpy="0 0 0" />
      <geometry>
        <mesh
          filename="package://pai_description/meshes/R_calf.STL" />
      </geometry>
      <material
        name="">
        <color
          rgba="1 1 1 1" />
      </material>
    </visual>
    <collision>
      <origin
        xyz="0 0 0"
        rpy="0 0 0" />
      <geometry>
        <mesh
          filename="package://pai_description/meshes/R_calf.STL" />
      </geometry>
    </collision>
  </link>
  <joint
    name="R_calf_joint"
    type="continuous">
    <origin
      xyz="0 0 -0.15"
      rpy="0 0 0" />
    <parent
      link="R_thigh" />
    <child
      link="R_calf" />
    <axis
      xyz="0 -1 0" />
  </joint>
  <link
    name="R_toe">
    <inertial>
      <origin
        xyz="0.010818 -1.9984E-08 -0.014672"
        rpy="0 0 0" />
      <mass
        value="0.09" />
      <inertia
        ixx="2.76E-06"
        ixy="3.1498E-11"
        ixz="1.0465E-06"
        iyy="2.7107E-05"
        iyz="3.7297E-13"
        izz="2.6942E-05" />
    </inertial>
    <visual>
      <origin
        xyz="0 0 0"
        rpy="0 0 0" />
      <geometry>
        <mesh
          filename="package://pai_description/meshes/R_toe.STL" />
      </geometry>
      <material
        name="">
        <color
          rgba="1 1 1 1" />
      </material>
    </visual>
    <collision>
      <origin
        xyz="0 0 0"
        rpy="0 0 0" />
      <geometry>
        <mesh
          filename="package://pai_description/meshes/R_toe.STL" />
      </geometry>
    </collision>
  </link>
  <joint
    name="R_toe_joint"
    type="continuous">
    <origin
      xyz="0 0 -0.16"
      rpy="0 0 0" />
    <parent
      link="R_calf" />
    <child
      link="R_toe" />
    <axis
      xyz="0 -1 0" />
  </joint>

  <transmission name="L_hip_tran">
    <type>transmission_interface/SimpleTransmission</type>
    <joint name="L_hip_joint">
    <hardwareInterface>hardware_interface/EffortJointInterface</hardwareInterface>
    </joint>
    <actuator name="L_hip_motor">
    <hardwareInterface>hardware_interface/EffortJointInterface</hardwareInterface>
    <mechanicalReduction>1</mechanicalReduction>
    </actuator>
  </transmission>

  <transmission name="L_hip2_tran">
    <type>transmission_interface/SimpleTransmission</type>
    <joint name="L_hip2_joint">
    <hardwareInterface>hardware_interface/EffortJointInterface</hardwareInterface>
    </joint>
    <actuator name="L_hip2_motor">
    <hardwareInterface>hardware_interface/EffortJointInterface</hardwareInterface>
    <mechanicalReduction>1</mechanicalReduction>
    </actuator>
  </transmission>

  <transmission name="L_thigh_tran">
    <type>transmission_interface/SimpleTransmission</type>
    <joint name="L_thigh_joint">
    <hardwareInterface>hardware_interface/EffortJointInterface</hardwareInterface>
    </joint>
    <actuator name="L_thigh_motor">
    <hardwareInterface>hardware_interface/EffortJointInterface</hardwareInterface>
    <mechanicalReduction>1</mechanicalReduction>
    </actuator>
  </transmission>

  <transmission name="L_calf_tran">
    <type>transmission_interface/SimpleTransmission</type>
    <joint name="L_calf_joint">
    <hardwareInterface>hardware_interface/EffortJointInterface</hardwareInterface>
    </joint>
    <actuator name="L_calf_motor">
    <hardwareInterface>hardware_interface/EffortJointInterface</hardwareInterface>
    <mechanicalReduction>1</mechanicalReduction>
    </actuator>
  </transmission>

  <transmission name="L_toe_tran">
    <type>transmission_interface/SimpleTransmission</type>
    <joint name="L_toe_joint">
    <hardwareInterface>hardware_interface/EffortJointInterface</hardwareInterface>
    </joint>
    <actuator name="L_toe_motor">
    <hardwareInterface>hardware_interface/EffortJointInterface</hardwareInterface>
    <mechanicalReduction>1</mechanicalReduction>
    </actuator>
  </transmission>

    <transmission name="R_hip_tran">
    <type>transmission_interface/SimpleTransmission</type>
    <joint name="R_hip_joint">
    <hardwareInterface>hardware_interface/EffortJointInterface</hardwareInterface>
    </joint>
    <actuator name="R_hip_motor">
    <hardwareInterface>hardware_interface/EffortJointInterface</hardwareInterface>
    <mechanicalReduction>1</mechanicalReduction>
    </actuator>
  </transmission>

  <transmission name="R_hip2_tran">
    <type>transmission_interface/SimpleTransmission</type>
    <joint name="R_hip2_joint">
    <hardwareInterface>hardware_interface/EffortJointInterface</hardwareInterface>
    </joint>
    <actuator name="R_hip2_motor">
    <hardwareInterface>hardware_interface/EffortJointInterface</hardwareInterface>
    <mechanicalReduction>1</mechanicalReduction>
    </actuator>
  </transmission>

  <transmission name="R_thigh_tran">
    <type>transmission_interface/SimpleTransmission</type>
    <joint name="R_thigh_joint">
    <hardwareInterface>hardware_interface/EffortJointInterface</hardwareInterface>
    </joint>
    <actuator name="R_thigh_motor">
    <hardwareInterface>hardware_interface/EffortJointInterface</hardwareInterface>
    <mechanicalReduction>1</mechanicalReduction>
    </actuator>
  </transmission>

  <transmission name="R_calf_tran">
    <type>transmission_interface/SimpleTransmission</type>
    <joint name="R_calf_joint">
    <hardwareInterface>hardware_interface/EffortJointInterface</hardwareInterface>
    </joint>
    <actuator name="R_calf_motor">
    <hardwareInterface>hardware_interface/EffortJointInterface</hardwareInterface>
    <mechanicalReduction>1</mechanicalReduction>
    </actuator>
  </transmission>

  <transmission name="R_toe_tran">
    <type>transmission_interface/SimpleTransmission</type>
    <joint name="R_toe_joint">
    <hardwareInterface>hardware_interface/EffortJointInterface</hardwareInterface>
    </joint>
    <actuator name="R_toe_motor">
    <hardwareInterface>hardware_interface/EffortJointInterface</hardwareInterface>
    <mechanicalReduction>1</mechanicalReduction>
    </actuator>
  </transmission>

</robot>

